<?xml version="1.0"?>
<robot name="ur5e">
  <!-- create link fixed to the "world" -->
  <link name="world" />
  <!-- links -  main serial chain -->
  <link name="ur_base_link" />
  <link name="ur_base_link_inertia">
    <visual>
      <origin rpy="0 0 3.141592653589793" xyz="0 0 0" />
      <geometry>
        <mesh filename="package://ur_description/meshes/ur5e/visual/base.dae" />
      </geometry>
    </visual>
    <collision>
      <origin rpy="0 0 3.141592653589793" xyz="0 0 0" />
      <geometry>
        <mesh filename="package://ur_description/meshes/ur5e/collision/base.stl" />
      </geometry>
    </collision>
    <inertial>
      <mass value="4.0" />
      <origin rpy="0 0 0" xyz="0 0 0" />
      <inertia ixx="0.00443333156" ixy="0.0" ixz="0.0" iyy="0.00443333156" iyz="0.0" izz="0.0072" />
    </inertial>
  </link>
  <link name="ur_shoulder_link">
    <visual>
      <origin rpy="0 0 3.141592653589793" xyz="0 0 0" />
      <geometry>
        <mesh filename="package://ur_description/meshes/ur5e/visual/shoulder.dae" />
      </geometry>
    </visual>
    <collision>
      <origin rpy="0 0 3.141592653589793" xyz="0 0 0" />
      <geometry>
        <mesh filename="package://ur_description/meshes/ur5e/collision/shoulder.stl" />
      </geometry>
    </collision>
    <inertial>
      <mass value="3.761" />
      <origin rpy="0 0 0" xyz="0 0 0" />
      <inertia ixx="0.01043677082529" ixy="0.0" ixz="0.0" iyy="0.01043677082529" iyz="0.0"
        izz="0.006769799999999999" />
    </inertial>
  </link>
  <link name="ur_upper_arm_link">
    <visual>
      <origin rpy="1.5707963267948966 0 -1.5707963267948966" xyz="0 0 0.138" />
      <geometry>
        <mesh filename="package://ur_description/meshes/ur5e/visual/upperarm.dae" />
      </geometry>
    </visual>
    <collision>
      <origin rpy="1.5707963267948966 0 -1.5707963267948966" xyz="0 0 0.138" />
      <geometry>
        <mesh filename="package://ur_description/meshes/ur5e/collision/upperarm.stl" />
      </geometry>
    </collision>
    <inertial>
      <mass value="8.058" />
      <origin rpy="0 1.5707963267948966 0" xyz="-0.2125 0.0 0.138" />
      <inertia ixx="0.128541836083245" ixy="0.0" ixz="0.0" iyy="0.128541836083245" iyz="0.0"
        izz="0.014504399999999999" />
    </inertial>
  </link>
  <link name="ur_forearm_link">
    <visual>
      <origin rpy="1.5707963267948966 0 -1.5707963267948966" xyz="0 0 0.007" />
      <geometry>
        <mesh filename="package://ur_description/meshes/ur5e/visual/forearm.dae" />
      </geometry>
    </visual>
    <collision>
      <origin rpy="1.5707963267948966 0 -1.5707963267948966" xyz="0 0 0.007" />
      <geometry>
        <mesh filename="package://ur_description/meshes/ur5e/collision/forearm.stl" />
      </geometry>
    </collision>
    <inertial>
      <mass value="2.846" />
      <origin rpy="0 1.5707963267948966 0" xyz="-0.1961 0.0 0.007" />
      <inertia ixx="0.03904256026963631" ixy="0.0" ixz="0.0" iyy="0.03904256026963631" iyz="0.0"
        izz="0.005122799999999999" />
    </inertial>
  </link>
  <link name="ur_wrist_1_link">
    <visual>
      <origin rpy="1.5707963267948966 0 0" xyz="0 0 -0.127" />
      <geometry>
        <mesh filename="package://ur_description/meshes/ur5e/visual/wrist1.dae" />
      </geometry>
    </visual>
    <collision>
      <origin rpy="1.5707963267948966 0 0" xyz="0 0 -0.127" />
      <geometry>
        <mesh filename="package://ur_description/meshes/ur5e/collision/wrist1.stl" />
      </geometry>
    </collision>
    <inertial>
      <mass value="1.37" />
      <origin rpy="0 0 0" xyz="0 0 0" />
      <inertia ixx="0.0028769988492000002" ixy="0.0" ixz="0.0" iyy="0.0028769988492000002" iyz="0.0"
        izz="0.0024660000000000003" />
    </inertial>
  </link>
  <link name="ur_wrist_2_link">
    <visual>
      <origin rpy="0 0 0" xyz="0 0 -0.0997" />
      <geometry>
        <mesh filename="package://ur_description/meshes/ur5e/visual/wrist2.dae" />
      </geometry>
    </visual>
    <collision>
      <origin rpy="0 0 0" xyz="0 0 -0.0997" />
      <geometry>
        <mesh filename="package://ur_description/meshes/ur5e/collision/wrist2.stl" />
      </geometry>
    </collision>
    <inertial>
      <mass value="1.3" />
      <origin rpy="0 0 0" xyz="0 0 0" />
      <inertia ixx="0.002729998908" ixy="0.0" ixz="0.0" iyy="0.002729998908" iyz="0.0" izz="0.00234" />
    </inertial>
  </link>
  <link name="ur_wrist_3_link">
    <visual>
      <origin rpy="1.5707963267948966 0 0" xyz="0 0 -0.0989" />
      <geometry>
        <mesh filename="package://ur_description/meshes/ur5e/visual/wrist3.dae" />
      </geometry>
    </visual>
    <collision>
      <origin rpy="1.5707963267948966 0 0" xyz="0 0 -0.0989" />
      <geometry>
        <mesh filename="package://ur_description/meshes/ur5e/collision/wrist3.stl" />
      </geometry>
    </collision>
    <inertial>
      <mass value="0.365" />
      <origin rpy="0 0 0" xyz="0.0 0.0 -0.0229" />
      <inertia ixx="0.00019212345231725498" ixy="0.0" ixz="0.0" iyy="0.00019212345231725498"
        iyz="0.0" izz="0.000256640625" />
    </inertial>
  </link>
  <!-- base_joint fixes base_link to the environment -->
  <joint name="ur_base_joint" type="fixed">
    <origin rpy="0 0 0" xyz="0 0 0" />
    <parent link="world" />
    <child link="ur_base_link" />
  </joint>
  <!-- joints - main serial chain -->
  <joint name="ur_base_link-base_link_inertia" type="fixed">
    <parent link="ur_base_link" />
    <child link="ur_base_link_inertia" />
    <!-- 'base_link' is REP-103 aligned (so X+ forward), while the internal
           frames of the robot/controller have X+ pointing backwards.
           Use the joint between 'base_link' and 'base_link_inertia' (a dummy
           link/frame) to introduce the necessary rotation over Z (of pi rad).
      -->
    <origin rpy="0 0 3.141592653589793" xyz="0 0 0" />
  </joint>
  <joint name="ur_shoulder_pan_joint" type="revolute">
    <parent link="ur_base_link_inertia" />
    <child link="ur_shoulder_link" />
    <origin rpy="0 0 0" xyz="0 0 0.1625" />
    <axis xyz="0 0 1" />
    <limit effort="150.0" lower="-6.283185307179586" upper="6.283185307179586"
      velocity="3.141592653589793" />
    <dynamics damping="0" friction="0" />
  </joint>
  <joint name="ur_shoulder_lift_joint" type="revolute">
    <parent link="ur_shoulder_link" />
    <child link="ur_upper_arm_link" />
    <origin rpy="1.570796327 0 0" xyz="0 0 0" />
    <axis xyz="0 0 1" />
    <limit effort="150.0" lower="-6.283185307179586" upper="6.283185307179586"
      velocity="3.141592653589793" />
    <dynamics damping="0" friction="0" />
  </joint>
  <joint name="ur_elbow_joint" type="revolute">
    <parent link="ur_upper_arm_link" />
    <child link="ur_forearm_link" />
    <origin rpy="0 0 0" xyz="-0.425 0 0" />
    <axis xyz="0 0 1" />
    <limit effort="150.0" lower="-3.141592653589793" upper="3.141592653589793"
      velocity="3.141592653589793" />
    <dynamics damping="0" friction="0" />
  </joint>
  <joint name="ur_wrist_1_joint" type="revolute">
    <parent link="ur_forearm_link" />
    <child link="ur_wrist_1_link" />
    <origin rpy="0 0 0" xyz="-0.3922 0 0.1333" />
    <axis xyz="0 0 1" />
    <limit effort="28.0" lower="-6.283185307179586" upper="6.283185307179586"
      velocity="3.141592653589793" />
    <dynamics damping="0" friction="0" />
  </joint>
  <joint name="ur_wrist_2_joint" type="revolute">
    <parent link="ur_wrist_1_link" />
    <child link="ur_wrist_2_link" />
    <origin rpy="1.570796327 0 0" xyz="0 -0.0997 -2.044881182297852e-11" />
    <axis xyz="0 0 1" />
    <limit effort="28.0" lower="-6.283185307179586" upper="6.283185307179586"
      velocity="3.141592653589793" />
    <dynamics damping="0" friction="0" />
  </joint>
  <joint name="ur_wrist_3_joint" type="revolute">
    <parent link="ur_wrist_2_link" />
    <child link="ur_wrist_3_link" />
    <origin rpy="1.570796326589793 3.141592653589793 3.141592653589793"
      xyz="0 0.0996 -2.042830148012698e-11" />
    <axis xyz="0 0 1" />
    <limit effort="28.0" lower="-6.283185307179586" upper="6.283185307179586"
      velocity="3.141592653589793" />
    <dynamics damping="0" friction="0" />
  </joint>
  <!-- ROS-Industrial 'base' frame - base_link to UR 'Base' Coordinates transform -->
  <link name="ur_base" />
  <joint name="ur_base_link-base_fixed_joint" type="fixed">
    <!-- Note the rotation over Z of pi radians - as base_link is REP-103
           aligned (i.e., has X+ forward, Y+ left and Z+ up), this is needed
           to correctly align 'base' with the 'Base' coordinate system of
           the UR controller.
      -->
    <origin rpy="0 0 3.141592653589793" xyz="0 0 0" />
    <parent link="ur_base_link" />
    <child link="ur_base" />
  </joint>
  <!-- ROS-Industrial 'flange' frame - attachment point for EEF models -->
  <link name="ur_flange" />
  <joint name="ur_wrist_3-flange" type="fixed">
    <parent link="ur_wrist_3_link" />
    <child link="ur_flange" />
    <origin rpy="0 -1.5707963267948966 -1.5707963267948966" xyz="0 0 0" />
  </joint>
  <!-- ROS-Industrial 'tool0' frame - all-zeros tool frame -->
  <link name="ur_tool0" />
  <joint name="ur_flange-tool0" type="fixed">
    <!-- default toolframe - X+ left, Y+ up, Z+ front -->
    <origin rpy="1.5707963267948966 0 1.5707963267948966" xyz="0 0 0" />
    <parent link="ur_flange" />
    <child link="ur_tool0" />
  </joint>
  <!-- Add URDF transmission elements (for ros_control) -->
  <!--<xacro:ur_arm_transmission
  prefix="${prefix}" hw_interface="${transmission_hw_interface}" />-->
  <!-- Placeholder for ros2_control transmission which don't yet exist -->
  <ros2_control name="ur5e" type="system">
    <hardware>
      <plugin>ur_robot_driver/URPositionHardwareInterface</plugin>
      <param name="robot_ip">192.168.56.101</param>
      <param name="script_filename">/ws/install/ur_client_library/share/ur_client_library/resources/external_control.urscript</param>
      <param name="output_recipe_filename">/ws/install/ur_robot_driver/share/ur_robot_driver/resources/rtde_output_recipe.txt</param>
      <param name="input_recipe_filename">/ws/install/ur_robot_driver/share/ur_robot_driver/resources/rtde_input_recipe.txt</param>
      <param name="headless_mode">True</param>
      <param name="reverse_port">50001</param>
      <param name="script_sender_port">50002</param>
      <param name="reverse_ip">0.0.0.0</param>
      <param name="script_command_port">50004</param>
      <param name="trajectory_port">50003</param>
      <param name="tf_prefix">ur_</param>
      <param name="non_blocking_read">True</param>
      <param name="servoj_gain">2000</param>
      <param name="servoj_lookahead_time">0.03</param>
      <param name="use_tool_communication">False</param>
      <param name="kinematics/hash">calib_12788084448423163542</param>
      <param name="tool_voltage">0</param>
      <param name="tool_parity">0</param>
      <param name="tool_baud_rate">115200</param>
      <param name="tool_stop_bits">1</param>
      <param name="tool_rx_idle_chars">1.5</param>
      <param name="tool_tx_idle_chars">3.5</param>
      <param name="tool_device_name">/tmp/ttyUR</param>
      <param name="tool_tcp_port">54321</param>
      <param name="robot_receive_timeout">0.04</param>
      <param name="force_mode_damping">0.005</param>
      <param name="force_mode_gain_scaling">1</param>
    </hardware>
    <joint name="ur_shoulder_pan_joint">
      <command_interface name="position" />
      <command_interface name="velocity" />
      <command_interface name="effort" />
      <state_interface name="position">
        <!-- initial position for the mock system and simulation -->
        <param name="initial_value">0.0</param>
      </state_interface>
      <state_interface name="velocity">
        <param name="initial_value">0.0</param>
      </state_interface>
      <state_interface name="effort">
        <param name="initial_value">0.0</param>
      </state_interface>
    </joint>
    <joint name="ur_shoulder_lift_joint">
      <command_interface name="position" />
      <command_interface name="velocity" />
      <command_interface name="effort" />
      <state_interface name="position">
        <!-- initial position for the mock system and simulation -->
        <param name="initial_value">-1.57</param>
      </state_interface>
      <state_interface name="velocity">
        <param name="initial_value">0.0</param>
      </state_interface>
      <state_interface name="effort">
        <param name="initial_value">0.0</param>
      </state_interface>
    </joint>
    <joint name="ur_elbow_joint">
      <command_interface name="position" />
      <command_interface name="velocity" />
      <command_interface name="effort" />
      <state_interface name="position">
        <!-- initial position for the mock system and simulation -->
        <param name="initial_value">0.0</param>
      </state_interface>
      <state_interface name="velocity">
        <param name="initial_value">0.0</param>
      </state_interface>
      <state_interface name="effort">
        <param name="initial_value">0.0</param>
      </state_interface>
    </joint>
    <joint name="ur_wrist_1_joint">
      <command_interface name="position" />
      <command_interface name="velocity" />
      <command_interface name="effort" />
      <state_interface name="position">
        <!-- initial position for the mock system and simulation -->
        <param name="initial_value">-1.57</param>
      </state_interface>
      <state_interface name="velocity">
        <param name="initial_value">0.0</param>
      </state_interface>
      <state_interface name="effort">
        <param name="initial_value">0.0</param>
      </state_interface>
    </joint>
    <joint name="ur_wrist_2_joint">
      <command_interface name="position" />
      <command_interface name="velocity" />
      <command_interface name="effort" />
      <state_interface name="position">
        <!-- initial position for the mock system and simulation -->
        <param name="initial_value">0.0</param>
      </state_interface>
      <state_interface name="velocity">
        <param name="initial_value">0.0</param>
      </state_interface>
      <state_interface name="effort">
        <param name="initial_value">0.0</param>
      </state_interface>
    </joint>
    <joint name="ur_wrist_3_joint">
      <command_interface name="position" />
      <command_interface name="velocity" />
      <command_interface name="effort" />
      <state_interface name="position">
        <!-- initial position for the mock system and simulation -->
        <param name="initial_value">0.0</param>
      </state_interface>
      <state_interface name="velocity">
        <param name="initial_value">0.0</param>
      </state_interface>
      <state_interface name="effort">
        <param name="initial_value">0.0</param>
      </state_interface>
    </joint>
    <sensor name="ur_tcp_fts_sensor">
      <state_interface name="force.x" />
      <state_interface name="force.y" />
      <state_interface name="force.z" />
      <state_interface name="torque.x" />
      <state_interface name="torque.y" />
      <state_interface name="torque.z" />
    </sensor>
    <!-- NOTE The following are joints used only for testing with mock hardware and will change in
    the future -->
    <gpio name="ur_speed_scaling">
      <state_interface name="speed_scaling_factor">
        <param name="initial_value">1.0</param>
      </state_interface>
      <command_interface name="target_speed_fraction_cmd" />
      <command_interface name="target_speed_fraction_async_success" />
    </gpio>
    <gpio name="ur_gpio">
      <command_interface name="standard_digital_output_cmd_0" />
      <command_interface name="standard_digital_output_cmd_1" />
      <command_interface name="standard_digital_output_cmd_2" />
      <command_interface name="standard_digital_output_cmd_3" />
      <command_interface name="standard_digital_output_cmd_4" />
      <command_interface name="standard_digital_output_cmd_5" />
      <command_interface name="standard_digital_output_cmd_6" />
      <command_interface name="standard_digital_output_cmd_7" />
      <command_interface name="standard_digital_output_cmd_8" />
      <command_interface name="standard_digital_output_cmd_9" />
      <command_interface name="standard_digital_output_cmd_10" />
      <command_interface name="standard_digital_output_cmd_11" />
      <command_interface name="standard_digital_output_cmd_12" />
      <command_interface name="standard_digital_output_cmd_13" />
      <command_interface name="standard_digital_output_cmd_14" />
      <command_interface name="standard_digital_output_cmd_15" />
      <command_interface name="standard_digital_output_cmd_16" />
      <command_interface name="standard_digital_output_cmd_17" />
      <command_interface name="standard_analog_output_cmd_0" />
      <command_interface name="standard_analog_output_cmd_1" />
      <command_interface name="tool_voltage_cmd" />
      <command_interface name="io_async_success" />
      <state_interface name="digital_output_0" />
      <state_interface name="digital_output_1" />
      <state_interface name="digital_output_2" />
      <state_interface name="digital_output_3" />
      <state_interface name="digital_output_4" />
      <state_interface name="digital_output_5" />
      <state_interface name="digital_output_6" />
      <state_interface name="digital_output_7" />
      <state_interface name="digital_output_8" />
      <state_interface name="digital_output_9" />
      <state_interface name="digital_output_10" />
      <state_interface name="digital_output_11" />
      <state_interface name="digital_output_12" />
      <state_interface name="digital_output_13" />
      <state_interface name="digital_output_14" />
      <state_interface name="digital_output_15" />
      <state_interface name="digital_output_16" />
      <state_interface name="digital_output_17" />
      <state_interface name="digital_input_0" />
      <state_interface name="digital_input_1" />
      <state_interface name="digital_input_2" />
      <state_interface name="digital_input_3" />
      <state_interface name="digital_input_4" />
      <state_interface name="digital_input_5" />
      <state_interface name="digital_input_6" />
      <state_interface name="digital_input_7" />
      <state_interface name="digital_input_8" />
      <state_interface name="digital_input_9" />
      <state_interface name="digital_input_10" />
      <state_interface name="digital_input_11" />
      <state_interface name="digital_input_12" />
      <state_interface name="digital_input_13" />
      <state_interface name="digital_input_14" />
      <state_interface name="digital_input_15" />
      <state_interface name="digital_input_16" />
      <state_interface name="digital_input_17" />
      <state_interface name="standard_analog_output_0" />
      <state_interface name="standard_analog_output_1" />
      <state_interface name="standard_analog_input_0" />
      <state_interface name="standard_analog_input_1" />
      <state_interface name="analog_io_type_0" />
      <state_interface name="analog_io_type_1" />
      <state_interface name="analog_io_type_2" />
      <state_interface name="analog_io_type_3" />
      <state_interface name="tool_mode" />
      <state_interface name="tool_output_voltage" />
      <state_interface name="tool_output_current" />
      <state_interface name="tool_temperature" />
      <state_interface name="tool_analog_input_0" />
      <state_interface name="tool_analog_input_1" />
      <state_interface name="tool_analog_input_type_0" />
      <state_interface name="tool_analog_input_type_1" />
      <state_interface name="robot_mode" />
      <state_interface name="robot_status_bit_0" />
      <state_interface name="robot_status_bit_1" />
      <state_interface name="robot_status_bit_2" />
      <state_interface name="robot_status_bit_3" />
      <state_interface name="safety_mode" />
      <state_interface name="safety_status_bit_0" />
      <state_interface name="safety_status_bit_1" />
      <state_interface name="safety_status_bit_2" />
      <state_interface name="safety_status_bit_3" />
      <state_interface name="safety_status_bit_4" />
      <state_interface name="safety_status_bit_5" />
      <state_interface name="safety_status_bit_6" />
      <state_interface name="safety_status_bit_7" />
      <state_interface name="safety_status_bit_8" />
      <state_interface name="safety_status_bit_9" />
      <state_interface name="safety_status_bit_10" />
      <state_interface name="program_running" />
    </gpio>
    <gpio name="ur_payload">
      <command_interface name="mass" />
      <command_interface name="cog.x" />
      <command_interface name="cog.y" />
      <command_interface name="cog.z" />
      <command_interface name="payload_async_success" />
    </gpio>
    <gpio name="ur_resend_robot_program">
      <command_interface name="resend_robot_program_cmd" />
      <command_interface name="resend_robot_program_async_success" />
    </gpio>
    <gpio name="ur_hand_back_control">
      <command_interface name="hand_back_control_cmd" />
      <command_interface name="hand_back_control_async_success" />
    </gpio>
    <gpio name="ur_zero_ftsensor">
      <command_interface name="zero_ftsensor_cmd" />
      <command_interface name="zero_ftsensor_async_success" />
    </gpio>
    <gpio name="ur_system_interface">
      <state_interface name="initialized" />
    </gpio>
    <gpio name="ur_force_mode">
      <command_interface name="selection_vector_x" />
      <command_interface name="selection_vector_y" />
      <command_interface name="selection_vector_z" />
      <command_interface name="selection_vector_rx" />
      <command_interface name="selection_vector_ry" />
      <command_interface name="selection_vector_rz" />
      <command_interface name="wrench_x" />
      <command_interface name="wrench_y" />
      <command_interface name="wrench_z" />
      <command_interface name="wrench_rx" />
      <command_interface name="wrench_ry" />
      <command_interface name="wrench_rz" />
      <command_interface name="limits_x" />
      <command_interface name="limits_y" />
      <command_interface name="limits_z" />
      <command_interface name="limits_rx" />
      <command_interface name="limits_ry" />
      <command_interface name="limits_rz" />
    </gpio>
    <gpio name="ur_double_registers">
      <state_interface name="output_double_register_24" />
      <command_interface name="input_double_register_24" />
    </gpio>
  </ros2_control>
</robot>