<?xml version="1.0"?>
<robot name="ur5e">
  <!-- create link fixed to the "world" -->
  <link name="world" />
  <!-- links -  main serial chain -->
  <link name="ur_base_link" />
  <link name="ur_base_link_inertia">
    <visual>
      <origin rpy="0 0 3.141592653589793" xyz="0 0 0" />
      <geometry>
        <mesh filename="package://ur_description/meshes/ur5e/visual/base.dae" />
      </geometry>
    </visual>
    <collision>
      <origin rpy="0 0 3.141592653589793" xyz="0 0 0" />
      <geometry>
        <mesh filename="package://ur_description/meshes/ur5e/collision/base.stl" />
      </geometry>
    </collision>
    <inertial>
      <mass value="4.0" />
      <origin rpy="0 0 0" xyz="0 0 0" />
      <inertia ixx="0.00443333156" ixy="0.0" ixz="0.0" iyy="0.00443333156" iyz="0.0" izz="0.0072" />
    </inertial>
  </link>
  <link name="ur_shoulder_link">
    <visual>
      <origin rpy="0 0 3.141592653589793" xyz="0 0 0" />
      <geometry>
        <mesh filename="package://ur_description/meshes/ur5e/visual/shoulder.dae" />
      </geometry>
    </visual>
    <collision>
      <origin rpy="0 0 3.141592653589793" xyz="0 0 0" />
      <geometry>
        <mesh filename="package://ur_description/meshes/ur5e/collision/shoulder.stl" />
      </geometry>
    </collision>
    <inertial>
      <mass value="3.761" />
      <origin rpy="0 0 0" xyz="0 0 0" />
      <inertia ixx="0.01043677082529" ixy="0.0" ixz="0.0" iyy="0.01043677082529" iyz="0.0"
        izz="0.006769799999999999" />
    </inertial>
  </link>
  <link name="ur_upper_arm_link">
    <visual>
      <origin rpy="1.5707963267948966 0 -1.5707963267948966" xyz="0 0 0.138" />
      <geometry>
        <mesh filename="package://ur_description/meshes/ur5e/visual/upperarm.dae" />
      </geometry>
    </visual>
    <collision>
      <origin rpy="1.5707963267948966 0 -1.5707963267948966" xyz="0 0 0.138" />
      <geometry>
        <mesh filename="package://ur_description/meshes/ur5e/collision/upperarm.stl" />
      </geometry>
    </collision>
    <inertial>
      <mass value="8.058" />
      <origin rpy="0 1.5707963267948966 0" xyz="-0.2125 0.0 0.138" />
      <inertia ixx="0.128541836083245" ixy="0.0" ixz="0.0" iyy="0.128541836083245" iyz="0.0"
        izz="0.014504399999999999" />
    </inertial>
  </link>
  <link name="ur_forearm_link">
    <visual>
      <origin rpy="1.5707963267948966 0 -1.5707963267948966" xyz="0 0 0.007" />
      <geometry>
        <mesh filename="package://ur_description/meshes/ur5e/visual/forearm.dae" />
      </geometry>
    </visual>
    <collision>
      <origin rpy="1.5707963267948966 0 -1.5707963267948966" xyz="0 0 0.007" />
      <geometry>
        <mesh filename="package://ur_description/meshes/ur5e/collision/forearm.stl" />
      </geometry>
    </collision>
    <inertial>
      <mass value="2.846" />
      <origin rpy="0 1.5707963267948966 0" xyz="-0.1961 0.0 0.007" />
      <inertia ixx="0.03904256026963631" ixy="0.0" ixz="0.0" iyy="0.03904256026963631" iyz="0.0"
        izz="0.005122799999999999" />
    </inertial>
  </link>
  <link name="ur_wrist_1_link">
    <visual>
      <origin rpy="1.5707963267948966 0 0" xyz="0 0 -0.127" />
      <geometry>
        <mesh filename="package://ur_description/meshes/ur5e/visual/wrist1.dae" />
      </geometry>
    </visual>
    <collision>
      <origin rpy="1.5707963267948966 0 0" xyz="0 0 -0.127" />
      <geometry>
        <mesh filename="package://ur_description/meshes/ur5e/collision/wrist1.stl" />
      </geometry>
    </collision>
    <inertial>
      <mass value="1.37" />
      <origin rpy="0 0 0" xyz="0 0 0" />
      <inertia ixx="0.0028769988492000002" ixy="0.0" ixz="0.0" iyy="0.0028769988492000002" iyz="0.0"
        izz="0.0024660000000000003" />
    </inertial>
  </link>
  <link name="ur_wrist_2_link">
    <visual>
      <origin rpy="0 0 0" xyz="0 0 -0.0997" />
      <geometry>
        <mesh filename="package://ur_description/meshes/ur5e/visual/wrist2.dae" />
      </geometry>
    </visual>
    <collision>
      <origin rpy="0 0 0" xyz="0 0 -0.0997" />
      <geometry>
        <mesh filename="package://ur_description/meshes/ur5e/collision/wrist2.stl" />
      </geometry>
    </collision>
    <inertial>
      <mass value="1.3" />
      <origin rpy="0 0 0" xyz="0 0 0" />
      <inertia ixx="0.002729998908" ixy="0.0" ixz="0.0" iyy="0.002729998908" iyz="0.0" izz="0.00234" />
    </inertial>
  </link>
  <link name="ur_wrist_3_link">
    <visual>
      <origin rpy="1.5707963267948966 0 0" xyz="0 0 -0.0989" />
      <geometry>
        <mesh filename="package://ur_description/meshes/ur5e/visual/wrist3.dae" />
      </geometry>
    </visual>
    <collision>
      <origin rpy="1.5707963267948966 0 0" xyz="0 0 -0.0989" />
      <geometry>
        <mesh filename="package://ur_description/meshes/ur5e/collision/wrist3.stl" />
      </geometry>
    </collision>
    <inertial>
      <mass value="0.365" />
      <origin rpy="0 0 0" xyz="0.0 0.0 -0.0229" />
      <inertia ixx="0.00019212345231725498" ixy="0.0" ixz="0.0" iyy="0.00019212345231725498"
        iyz="0.0" izz="0.000256640625" />
    </inertial>
  </link>
  <!-- base_joint fixes base_link to the environment -->
  <joint name="ur_base_joint" type="fixed">
    <origin rpy="0 0 0" xyz="0 0 0" />
    <parent link="world" />
    <child link="ur_base_link" />
  </joint>
  <!-- joints - main serial chain -->
  <joint name="ur_base_link-base_link_inertia" type="fixed">
    <parent link="ur_base_link" />
    <child link="ur_base_link_inertia" />
    <!-- 'base_link' is REP-103 aligned (so X+ forward), while the internal
           frames of the robot/controller have X+ pointing backwards.
           Use the joint between 'base_link' and 'base_link_inertia' (a dummy
           link/frame) to introduce the necessary rotation over Z (of pi rad).
      -->
    <origin rpy="0 0 3.141592653589793" xyz="0 0 0" />
  </joint>
  <joint name="ur_shoulder_pan_joint" type="revolute">
    <parent link="ur_base_link_inertia" />
    <child link="ur_shoulder_link" />
    <origin rpy="0 0 0" xyz="0 0 0.1625" />
    <axis xyz="0 0 1" />
    <limit effort="150.0" lower="-6.283185307179586" upper="6.283185307179586"
      velocity="3.141592653589793" />
    <dynamics damping="0" friction="0" />
  </joint>
  <joint name="ur_shoulder_lift_joint" type="revolute">
    <parent link="ur_shoulder_link" />
    <child link="ur_upper_arm_link" />
    <origin rpy="1.570796327 0 0" xyz="0 0 0" />
    <axis xyz="0 0 1" />
    <limit effort="150.0" lower="-6.283185307179586" upper="6.283185307179586"
      velocity="3.141592653589793" />
    <dynamics damping="0" friction="0" />
  </joint>
  <joint name="ur_elbow_joint" type="revolute">
    <parent link="ur_upper_arm_link" />
    <child link="ur_forearm_link" />
    <origin rpy="0 0 0" xyz="-0.425 0 0" />
    <axis xyz="0 0 1" />
    <limit effort="150.0" lower="-3.141592653589793" upper="3.141592653589793"
      velocity="3.141592653589793" />
    <dynamics damping="0" friction="0" />
  </joint>
  <joint name="ur_wrist_1_joint" type="revolute">
    <parent link="ur_forearm_link" />
    <child link="ur_wrist_1_link" />
    <origin rpy="0 0 0" xyz="-0.3922 0 0.1333" />
    <axis xyz="0 0 1" />
    <limit effort="28.0" lower="-6.283185307179586" upper="6.283185307179586"
      velocity="3.141592653589793" />
    <dynamics damping="0" friction="0" />
  </joint>
  <joint name="ur_wrist_2_joint" type="revolute">
    <parent link="ur_wrist_1_link" />
    <child link="ur_wrist_2_link" />
    <origin rpy="1.570796327 0 0" xyz="0 -0.0997 -2.044881182297852e-11" />
    <axis xyz="0 0 1" />
    <limit effort="28.0" lower="-6.283185307179586" upper="6.283185307179586"
      velocity="3.141592653589793" />
    <dynamics damping="0" friction="0" />
  </joint>
  <joint name="ur_wrist_3_joint" type="revolute">
    <parent link="ur_wrist_2_link" />
    <child link="ur_wrist_3_link" />
    <origin rpy="1.570796326589793 3.141592653589793 3.141592653589793"
      xyz="0 0.0996 -2.042830148012698e-11" />
    <axis xyz="0 0 1" />
    <limit effort="28.0" lower="-6.283185307179586" upper="6.283185307179586"
      velocity="3.141592653589793" />
    <dynamics damping="0" friction="0" />
  </joint>
  <!-- ROS-Industrial 'base' frame - base_link to UR 'Base' Coordinates transform -->
  <link name="ur_base" />
  <joint name="ur_base_link-base_fixed_joint" type="fixed">
    <!-- Note the rotation over Z of pi radians - as base_link is REP-103
           aligned (i.e., has X+ forward, Y+ left and Z+ up), this is needed
           to correctly align 'base' with the 'Base' coordinate system of
           the UR controller.
      -->
    <origin rpy="0 0 3.141592653589793" xyz="0 0 0" />
    <parent link="ur_base_link" />
    <child link="ur_base" />
  </joint>
  <!-- ROS-Industrial 'flange' frame - attachment point for EEF models -->
  <link name="ur_flange" />
  <joint name="ur_wrist_3-flange" type="fixed">
    <parent link="ur_wrist_3_link" />
    <child link="ur_flange" />
    <origin rpy="0 -1.5707963267948966 -1.5707963267948966" xyz="0 0 0" />
  </joint>
  <!-- ROS-Industrial 'tool0' frame - all-zeros tool frame -->
  <link name="ur_tool0" />
  <joint name="ur_flange-tool0" type="fixed">
    <!-- default toolframe - X+ left, Y+ up, Z+ front -->
    <origin rpy="1.5707963267948966 0 1.5707963267948966" xyz="0 0 0" />
    <parent link="ur_flange" />
    <child link="ur_tool0" />
  </joint>
  <!-- Add URDF transmission elements (for ros_control) -->
  <!--<xacro:ur_arm_transmission
  prefix="${prefix}" hw_interface="${transmission_hw_interface}" />-->
  <!-- Placeholder for ros2_control transmission which don't yet exist -->
  <ros2_control name="ur5e_mock" type="system">
    <hardware>
      <plugin>aica_core_interfaces/MockInterface</plugin>
    </hardware>
    <joint name="ur_shoulder_pan_joint">
      <command_interface name="position" />
      <command_interface name="velocity" />
      <command_interface name="effort" />
      <state_interface name="position">
        <!-- initial position for the mock system and simulation -->
        <param name="initial_value">0.0</param>
      </state_interface>
      <state_interface name="velocity">
        <param name="initial_value">0.0</param>
      </state_interface>
      <state_interface name="effort">
        <param name="initial_value">0.0</param>
      </state_interface>
      <param name="initial_position">0.0</param>
    </joint>
    <joint name="ur_shoulder_lift_joint">
      <command_interface name="position" />
      <command_interface name="velocity" />
      <command_interface name="effort" />
      <state_interface name="position">
        <!-- initial position for the mock system and simulation -->
        <param name="initial_value">-1.57</param>
      </state_interface>
      <state_interface name="velocity">
        <param name="initial_value">0.0</param>
      </state_interface>
      <state_interface name="effort">
        <param name="initial_value">0.0</param>
      </state_interface>
      <param name="initial_position">-1.57</param>
    </joint>
    <joint name="ur_elbow_joint">
      <command_interface name="position" />
      <command_interface name="velocity" />
      <command_interface name="effort" />
      <state_interface name="position">
        <!-- initial position for the mock system and simulation -->
        <param name="initial_value">0.0</param>
      </state_interface>
      <state_interface name="velocity">
        <param name="initial_value">0.0</param>
      </state_interface>
      <state_interface name="effort">
        <param name="initial_value">0.0</param>
      </state_interface>
      <param name="initial_position">1.57</param>
    </joint>
    <joint name="ur_wrist_1_joint">
      <command_interface name="position" />
      <command_interface name="velocity" />
      <command_interface name="effort" />
      <state_interface name="position">
        <!-- initial position for the mock system and simulation -->
        <param name="initial_value">-1.57</param>
      </state_interface>
      <state_interface name="velocity">
        <param name="initial_value">0.0</param>
      </state_interface>
      <state_interface name="effort">
        <param name="initial_value">0.0</param>
      </state_interface>
      <param name="initial_position">-1.57</param>
    </joint>
    <joint name="ur_wrist_2_joint">
      <command_interface name="position" />
      <command_interface name="velocity" />
      <command_interface name="effort" />
      <state_interface name="position">
        <!-- initial position for the mock system and simulation -->
        <param name="initial_value">0.0</param>
      </state_interface>
      <state_interface name="velocity">
        <param name="initial_value">0.0</param>
      </state_interface>
      <state_interface name="effort">
        <param name="initial_value">0.0</param>
      </state_interface>
      <param name="initial_position">-1.57</param>
    </joint>
    <joint name="ur_wrist_3_joint">
      <command_interface name="position" />
      <command_interface name="velocity" />
      <command_interface name="effort" />
      <state_interface name="position">
        <!-- initial position for the mock system and simulation -->
        <param name="initial_value">0.0</param>
      </state_interface>
      <state_interface name="velocity">
        <param name="initial_value">0.0</param>
      </state_interface>
      <state_interface name="effort">
        <param name="initial_value">0.0</param>
      </state_interface>
      <param name="initial_position">0.0</param>
    </joint>
  </ros2_control>
</robot>